<?xml version="1.0"?>
<robot name="simple_robot" xmlns:xacro="http://www.ros.org/wiki/xacro"> 

    <!-- Start of Links - first link must be a non-inertial link -->
    <link name="base_link">
    </link> 
	
    <link name="chassis">
        <inertial>
            <mass value="1"/>
            <inertia ixx="0.004" ixy="0.0" ixz="0.0" iyy="0.004" iyz="0.0" izz="0.002"/>
        </inertial>
        <collision name="chassis">
            <geometry>
                <box size=".4 .2 .1" />
            </geometry>
        </collision>
        <visual name="chassis">
            <geometry>
                <box size=".4 .2 .1" />
            </geometry>
        </visual>
    </link>       

    <link name="castor">
        <inertial>
            <mass value=".1"/>
            <inertia ixx="0.004" ixy="0.0" ixz="0.0" iyy="0.004" iyz="0.0" izz="0.002"/>
        </inertial>
        <collision name="castor">
            <geometry>
                <sphere radius=".05" />
            </geometry>
        </collision>              
        <visual name='visual'>
            <geometry>
                <sphere radius=".05" />
            </geometry>
        </visual>
    </link>     

    <link name="left_wheel">
        <inertial>
            <mass value=".5"/>
            <inertia ixx="0.004" ixy="0.0" ixz="0.0" iyy="0.004" iyz="0.0" izz="0.002"/>
        </inertial>
        <pose>0.1 0.13 0.1 0 1.5707 1.5707</pose>
        <collision name="left_wheel">
            <geometry>
                <cylinder radius='.1' length='.05'/>
            </geometry>
        </collision>
        <visual name="left_wheel">
            <geometry>
                <cylinder radius='.1' length='.05'/>
            </geometry>               
        </visual>
    </link> 
          
    <link name="right_wheel">
        <inertial>
            <mass value=".5"/>
            <inertia ixx="0.004" ixy="0.0" ixz="0.0" iyy="0.004" iyz="0.0" izz="0.002"/>
        </inertial>
        <pose>0.1 0.13 0.1 0 1.5707 1.5707</pose>
        <collision name="right_wheel">
            <geometry>
                <cylinder radius='.1' length='.05'/>
            </geometry>
        </collision>
        <visual name="right_wheel">
            <geometry>
                <cylinder radius='.1' length='.05'/>
            </geometry>         
        </visual>
    </link>            

    <!-- Start of Joints - connecting all links together -->

    <joint name="joint0" type="fixed">
        <parent link="base_link"/>
        <child link="chassis"/>
        <origin xyz="0 0 0" rpy="0 0 0"/>
        <axis xyz="0 1 0"/>
        <dynamics damping="0.7"/>
    </joint>
    
    <joint name="joint1" type="fixed">
        <parent link="chassis"/>
        <child link="castor"/>
        <origin xyz=".15 0 -.05" rpy="0 0 0"/>
        <axis xyz="0 1 0"/>
        <dynamics damping="0.7"/>
    </joint>

    <joint type="continuous" name="wheel_left_joint">
        <parent link="chassis"/>
        <child link="left_wheel"/>
        <origin xyz="-0.1 0.13 0" rpy="0 1.5707 1.5707"/>
        <axis xyz="0 0 1"/>
        <calibration rising="0.0"/>
        <dynamics damping="0.0" friction="0.0"/>
        <limit effort="30" velocity="2.0" />
        <safety_controller k_velocity="10" k_position="15" soft_lower_limit="-2.0" soft_upper_limit="0.5" />
    </joint>

    <joint type="continuous" name="wheel_right_joint">
        <parent link="chassis"/>
        <child link="right_wheel"/>
        <origin xyz="-0.1 -0.13 0" rpy="0 1.5707 1.5707"/>
        <axis xyz="0 0 1"/>
        <calibration rising="0.0"/>
        <dynamics damping="0.0" friction="0.0"/>
        <limit effort="30" velocity="2.0" />
        <safety_controller k_velocity="10" k_position="15" soft_lower_limit="-2.0" soft_upper_limit="0.5" />
    </joint>
    
    <!-- Transmissions are where the ros_controller interacts -->
    <ros2_control name="GazeboSystem" type="system">
      <hardware>
        <plugin>gazebo_ros2_control/GazeboSystem</plugin>
      </hardware>
      <joint name="wheel_left_joint">
        <command_interface name="velocity">
          <param name="min">-1</param>
          <param name="max">1</param>
        </command_interface>
        <state_interface name="position">
          <param name="initial_value">0.0</param>
        </state_interface>
        <state_interface name="velocity">
          <param name="initial_value">0.0</param>
        </state_interface>
      </joint>
      <joint name="wheel_right_joint">
        <command_interface name="velocity">
          <param name="min">-1</param>
          <param name="max">1</param>
        </command_interface>
        <state_interface name="position">
          <param name="initial_value">0.0</param>
        </state_interface>
        <state_interface name="velocity">
          <param name="initial_value">0.0</param>
        </state_interface>
      </joint>
    </ros2_control>
    
  <gazebo>
    <!-- Joint state publisher -->
    <plugin filename="libgazebo_ros2_control.so" name="gazebo_ros2_control">
      <parameters>$(find simple_robot_ros2)/config/simple_diff_drive.yaml</parameters>
      <!-- parameters>$(find simple_robot_ros2)/config/diff_drive_controller.yaml</parameters>-->
    </plugin>
  </gazebo>  

  <gazebo reference="chassis">
  	<material>Gazebo/Green</material>
    	<mu1>.01</mu1>
    	<mu2>.01</mu2>  	
        <fdir1>0.000000 0.000000 0.000000</fdir1>
        <slip1>1.000000</slip1>
        <slip2>1.000000</slip2>   	  
  </gazebo>  
  
  <gazebo reference="left_wheel">
    	<material>Gazebo/Red</material>
    	<mu1>100000</mu1>
    	<mu2>100000</mu2>
        <fdir1>0.000000 0.000000 0.000000</fdir1>
        <slip1>0.000000</slip1>
        <slip2>0.000000</slip2>    
  </gazebo>  

  <gazebo reference="right_wheel">
    	<material>Gazebo/Yellow</material>
    	<mu1>100000</mu1>
    	<mu2>100000</mu2>  	
        <fdir1>0.000000 0.000000 0.000000</fdir1>
        <slip1>0.000000</slip1>
        <slip2>0.000000</slip2>    
  </gazebo>  
  <gazebo reference="castor">
  	<material>Gazebo/Blue</material>
    	<mu1>.01</mu1>
    	<mu2>.01</mu2>  	
        <fdir1>0.000000 0.000000 0.000000</fdir1>
        <slip1>1.000000</slip1>
        <slip2>1.000000</slip2>     	
  </gazebo>  

</robot>
